INFO:     Will watch for changes in these directories: ['/content']
INFO:     Uvicorn running on http://127.0.0.1:8000 (Press CTRL+C to quit)
INFO:     Started reloader process [337] using statreload
2022-01-13 08:39:20.549440: E tensorflow/stream_executor/cuda/cuda_driver.cc:271] failed call to cuInit: CUDA_ERROR_NO_DEVICE: no CUDA-capable device is detected
INFO:     Started server process [340]
INFO:     Waiting for application startup.
INFO:     Application startup complete.
INFO:     127.0.0.1:42842 - "POST /predict HTTP/1.1" 500 Internal Server Error
ERROR:    Exception in ASGI application
Traceback (most recent call last):
  File "/usr/local/lib/python3.7/dist-packages/uvicorn/protocols/http/h11_impl.py", line 373, in run_asgi
    result = await app(self.scope, self.receive, self.send)
  File "/usr/local/lib/python3.7/dist-packages/uvicorn/middleware/proxy_headers.py", line 75, in __call__
    return await self.app(scope, receive, send)
  File "/usr/local/lib/python3.7/dist-packages/fastapi/applications.py", line 208, in __call__
    await super().__call__(scope, receive, send)
  File "/usr/local/lib/python3.7/dist-packages/starlette/applications.py", line 112, in __call__
    await self.middleware_stack(scope, receive, send)
  File "/usr/local/lib/python3.7/dist-packages/starlette/middleware/errors.py", line 181, in __call__
    raise exc
  File "/usr/local/lib/python3.7/dist-packages/starlette/middleware/errors.py", line 159, in __call__
    await self.app(scope, receive, _send)
  File "/usr/local/lib/python3.7/dist-packages/starlette/exceptions.py", line 82, in __call__
    raise exc
  File "/usr/local/lib/python3.7/dist-packages/starlette/exceptions.py", line 71, in __call__
    await self.app(scope, receive, sender)
  File "/usr/local/lib/python3.7/dist-packages/starlette/routing.py", line 656, in __call__
    await route.handle(scope, receive, send)
  File "/usr/local/lib/python3.7/dist-packages/starlette/routing.py", line 259, in handle
    await self.app(scope, receive, send)
  File "/usr/local/lib/python3.7/dist-packages/starlette/routing.py", line 61, in app
    response = await func(request)
  File "/usr/local/lib/python3.7/dist-packages/fastapi/routing.py", line 227, in app
    dependant=dependant, values=values, is_coroutine=is_coroutine
  File "/usr/local/lib/python3.7/dist-packages/fastapi/routing.py", line 159, in run_endpoint_function
    return await dependant.call(**values)
  File "./main.py", line 8, in create_file
    return {"result": process(file)}
  File "./predict.py", line 18, in process
    image_file=Image.open(test_path).convert('L')
  File "/usr/local/lib/python3.7/dist-packages/PIL/Image.py", line 2843, in open
    fp = builtins.open(filename, "rb")
FileNotFoundError: [Errno 2] No such file or directory: 'mnist_6.jpg'
INFO:     127.0.0.1:45008 - "POST /predict HTTP/1.1" 500 Internal Server Error
ERROR:    Exception in ASGI application
Traceback (most recent call last):
  File "/usr/local/lib/python3.7/dist-packages/uvicorn/protocols/http/h11_impl.py", line 373, in run_asgi
    result = await app(self.scope, self.receive, self.send)
  File "/usr/local/lib/python3.7/dist-packages/uvicorn/middleware/proxy_headers.py", line 75, in __call__
    return await self.app(scope, receive, send)
  File "/usr/local/lib/python3.7/dist-packages/fastapi/applications.py", line 208, in __call__
    await super().__call__(scope, receive, send)
  File "/usr/local/lib/python3.7/dist-packages/starlette/applications.py", line 112, in __call__
    await self.middleware_stack(scope, receive, send)
  File "/usr/local/lib/python3.7/dist-packages/starlette/middleware/errors.py", line 181, in __call__
    raise exc
  File "/usr/local/lib/python3.7/dist-packages/starlette/middleware/errors.py", line 159, in __call__
    await self.app(scope, receive, _send)
  File "/usr/local/lib/python3.7/dist-packages/starlette/exceptions.py", line 82, in __call__
    raise exc
  File "/usr/local/lib/python3.7/dist-packages/starlette/exceptions.py", line 71, in __call__
    await self.app(scope, receive, sender)
  File "/usr/local/lib/python3.7/dist-packages/starlette/routing.py", line 656, in __call__
    await route.handle(scope, receive, send)
  File "/usr/local/lib/python3.7/dist-packages/starlette/routing.py", line 259, in handle
    await self.app(scope, receive, send)
  File "/usr/local/lib/python3.7/dist-packages/starlette/routing.py", line 61, in app
    response = await func(request)
  File "/usr/local/lib/python3.7/dist-packages/fastapi/routing.py", line 227, in app
    dependant=dependant, values=values, is_coroutine=is_coroutine
  File "/usr/local/lib/python3.7/dist-packages/fastapi/routing.py", line 159, in run_endpoint_function
    return await dependant.call(**values)
  File "./main.py", line 8, in create_file
    return {"result": process(file)}
  File "./predict.py", line 18, in process
    image_file=Image.open(test_path).convert('L')
  File "/usr/local/lib/python3.7/dist-packages/PIL/Image.py", line 2843, in open
    fp = builtins.open(filename, "rb")
FileNotFoundError: [Errno 2] No such file or directory: 'mnist_6.jpg'
WARNING:  StatReload detected file change in 'predict.py'. Reloading...
INFO:     Shutting down
INFO:     Waiting for application shutdown.
INFO:     Application shutdown complete.
INFO:     Finished server process [340]
2022-01-13 09:04:10.031619: E tensorflow/stream_executor/cuda/cuda_driver.cc:271] failed call to cuInit: CUDA_ERROR_NO_DEVICE: no CUDA-capable device is detected
WARNING:  StatReload detected file change in 'main.py'. Reloading...
2022-01-13 09:04:13.840932: E tensorflow/stream_executor/cuda/cuda_driver.cc:271] failed call to cuInit: CUDA_ERROR_NO_DEVICE: no CUDA-capable device is detected
INFO:     Started server process [596]
INFO:     Waiting for application startup.
INFO:     Application startup complete.
INFO:     Will watch for changes in these directories: ['/content']
ERROR:    [Errno 98] Address already in use
INFO:     127.0.0.1:45404 - "POST /predict HTTP/1.1" 500 Internal Server Error
ERROR:    Exception in ASGI application
Traceback (most recent call last):
  File "/usr/local/lib/python3.7/dist-packages/uvicorn/protocols/http/h11_impl.py", line 373, in run_asgi
    result = await app(self.scope, self.receive, self.send)
  File "/usr/local/lib/python3.7/dist-packages/uvicorn/middleware/proxy_headers.py", line 75, in __call__
    return await self.app(scope, receive, send)
  File "/usr/local/lib/python3.7/dist-packages/fastapi/applications.py", line 208, in __call__
    await super().__call__(scope, receive, send)
  File "/usr/local/lib/python3.7/dist-packages/starlette/applications.py", line 112, in __call__
    await self.middleware_stack(scope, receive, send)
  File "/usr/local/lib/python3.7/dist-packages/starlette/middleware/errors.py", line 181, in __call__
    raise exc
  File "/usr/local/lib/python3.7/dist-packages/starlette/middleware/errors.py", line 159, in __call__
    await self.app(scope, receive, _send)
  File "/usr/local/lib/python3.7/dist-packages/starlette/exceptions.py", line 82, in __call__
    raise exc
  File "/usr/local/lib/python3.7/dist-packages/starlette/exceptions.py", line 71, in __call__
    await self.app(scope, receive, sender)
  File "/usr/local/lib/python3.7/dist-packages/starlette/routing.py", line 656, in __call__
    await route.handle(scope, receive, send)
  File "/usr/local/lib/python3.7/dist-packages/starlette/routing.py", line 259, in handle
    await self.app(scope, receive, send)
  File "/usr/local/lib/python3.7/dist-packages/starlette/routing.py", line 61, in app
    response = await func(request)
  File "/usr/local/lib/python3.7/dist-packages/fastapi/routing.py", line 227, in app
    dependant=dependant, values=values, is_coroutine=is_coroutine
  File "/usr/local/lib/python3.7/dist-packages/fastapi/routing.py", line 159, in run_endpoint_function
    return await dependant.call(**values)
  File "./main.py", line 8, in create_file
    return {"result": process(file)}
  File "./predict.py", line 18, in process
    image_file=Image.open(test_path).convert('L')
  File "/usr/local/lib/python3.7/dist-packages/PIL/Image.py", line 2843, in open
    fp = builtins.open(filename, "rb")
FileNotFoundError: [Errno 2] No such file or directory: 'mnist_6.jpg'
WARNING:  StatReload detected file change in 'predict.py'. Reloading...
INFO:     Shutting down
INFO:     Waiting for application shutdown.
INFO:     Application shutdown complete.
INFO:     Finished server process [596]
WARNING:  StatReload detected file change in 'main.py'. Reloading...
2022-01-13 09:05:41.749414: E tensorflow/stream_executor/cuda/cuda_driver.cc:271] failed call to cuInit: CUDA_ERROR_NO_DEVICE: no CUDA-capable device is detected
INFO:     Started server process [634]
INFO:     Waiting for application startup.
INFO:     Application startup complete.
INFO:     Will watch for changes in these directories: ['/content']
ERROR:    [Errno 98] Address already in use
INFO:     127.0.0.1:45682 - "POST /predict HTTP/1.1" 200 OK
